Workbook

Sheet Lista de Preço 02_2022
C1: Lista de Preços - 03/2022 - Leve e Pesada
P2: Atualizado em: 13/06/2022
L3: Em vigor: 01/07/2022 | P3: Verde: Lançamentos
A4: Código | B4: Preço | C4: Liquido S/Imp | D4: Preço C/Imp SP | E4: IPI | F4: ICMS SP | G4: Leve/Pesada | H4: Produto | I4: Aplicação | J4: Sub Grupo | K4: Montadora | L4: Nº Original | M4: NCM | N4: CEST | O4: Peso (Kg) | P4: Código de Barras | Q4: Múltiplos
A5: AL-01 | B5: 92.286751 | C5: ='Lista de Preço 02_2022'!$B5*0.9*0.9*0.9*0.9*0.9*0.97 -> 52.859572 | D5: ='Lista de Preço 02_2022'!$C5*1.1712 -> 61.90913 | E5: 3.25 | F5: 0.18 | G5: Leve | H5: CUBO DE RODA | I5: FORD - Escort 1.6 08/1980 > 08/1990; Escort Hobby < 1995; Escort III RS Turbo 11/1984 > 12/1985; Escort XR3 1.8 1982 > 1992; Escort XR3/i 1.6 08/1980 > 1992; Verona todos < 1992; VOLKSWAGEN - Apollo todos 1990 >; | J5: CR - Leve | K5: FORD | L5: 81AB1106BB | M5: 87089990 | N5: 01.075.00 | O5: 1.506 | P5: 7898233430014 | Q5: 1
A6: AL-02 | B6: 18.694503 | C6: ='Lista de Preço 02_2022'!$B6*0.9*0.9*0.9*0.9*0.9*0.97 -> 10.70775 | D6: ='Lista de Preço 02_2022'!$C6*1.1712 -> 12.540916 | E6: 3.25 | F6: 0.18 | G6: Leve | H6: CAMBIO/TRAMB. | I6: FORD - Escort Todos Todos; | J6: Diversos - Leve | K6: FORD | L6: 86AU 6A022-AA | M6: 87089990 | N6: 01.075.00 | O6: 0.634 | P6: 7898233430021 | Q6: 1
A7: AL-03 | B7: 20.247953 | C7: ='Lista de Preço 02_2022'!$B7*0.9*0.9*0.9*0.9*0.9*0.97 -> 11.597527 | D7: ='Lista de Preço 02_2022'!$C7*1.1712 -> 13.583024 | E7: 3.25 | F7: 0.18 | G7: Leve | H7: CAMBIO/TRAMB. | I7: FORD - Escort Todos Todos; | J7: Diversos - Leve | K7: FORD | L7: 86AU-6A069-AA | M7: 87089990 | N7: 01.075.00 | O7: 0.836 | P7: 7898233430038 | Q7: 1
A8: AL-04 | B8: 148.76189 | C8: ='Lista de Preço 02_2022'!$B8*0.9*0.9*0.9*0.9*0.9*0.97 -> 85.207139 | D8: ='Lista de Preço 02_2022'!$C8*1.1627 -> 99.070341 | E8: 2.6 | F8: 0.18 | G8: Pesada | H8: EMBREAGEM | I8: FORD - 100 ; 1000 ; 11000 ; 12000 MWM 1993/1998; 14000 MWM 1993/1998; 2000 ; 21000 ; 350 ; 400 ; 4000 ; 600 1972/1980; 700 1977/1980; 750 1972/1977; F100 ; F1000 ; F11000 ; F12000 1981/1982; F12000 1993/1998; F14000 1980/1992; F14000 1993/1998; F19000 1981/1982; F2000 ; F21000 ; F350 ; F400 ; F4000 ; F600 1972/1980; F700 1977/1980; F750 1972/1977; VOLKSWAGEN - 12.140H 1991/1998; | J8: LP - Pesada | K8: FORD | L8: TEG-141857 | M8: 87089300 | N8: 01.075.00 | O8: 0.866 | P8: 7898233430045 | Q8: 1
A9: AL-05 | B9: 57.62626 | C9: ='Lista de Preço 02_2022'!$B9*0.9*0.9*0.9*0.9*0.9*0.97 -> 33.006898 | D9: ='Lista de Preço 02_2022'!$C9*1.1712 -> 38.657679 | E9: 3.25 | F9: 0.18 | G9: Leve | H9: TRIZETA | I9: FORD - Belina II 1977/1986; Corcel II ; Del Rey 1982/1988; Pampa 4x2 1981/1989; Pampa 4x4 1983/...; Scala TA 1982/1988; Scala TM 1981/1989; RENAULT - Clio ; Laguna ; Logan 1.6/16V ; Megane ; Sandero 1.6/16V ; Scenic ; | J9: TZ - Leve | K9: FORD | L9: 83NU3W007A | M9: 87089990 | N9: 01.075.00 | O9: 0.334 | P9: 7898233430052 | Q9: 1
A10: AL-06 | B10: 3.6351569 | C10: ='Lista de Preço 02_2022'!$B10*0.9*0.9*0.9*0.9*0.9*0.97 -> 2.0821281 | D10: ='Lista de Preço 02_2022'!$C10*1.1712 -> 2.4385884 | E10: 3.25 | F10: 0.18 | G10: Leve | H10: SUSPENSÃO | I10: FORD - Escort .../1985; | J10: Diversos - Leve | K10: FORD | L10: 78EB-5488-AB | M10: 87089990 | N10: 01.075.00 | O10: 0.12 | P10: 7898233430069 | Q10: 1
A11: AL-07 | B11: 7.0104387 | C11: ='Lista de Preço 02_2022'!$B11*0.9*0.9*0.9*0.9*0.9*0.97 -> 4.0154061 | D11: ='Lista de Preço 02_2022'!$C11*1.1712 -> 4.7028437 | E11: 3.25 | F11: 0.18 | G11: Leve | H11: SUSPENSÃO | I11: FORD - Escort .../1986; | J11: Diversos - Leve | K11: FORD | L11: 86AU-5488-A | M11: 87089990 | N11: 01.075.00 | O11: 0.168 | P11: 7898233430076 | Q11: 1
A12: AL-08 | B12: 181.89521 | C12: ='Lista de Preço 02_2022'!$B12*0.9*0.9*0.9*0.9*0.9*0.97 -> 104.18509 | D12: ='Lista de Preço 02_2022'!$C12*1.1712 -> 122.02157 | E12: 3.25 | F12: 0.18 | G12: Leve | H12: TULIPA | I12: FORD - Belina 1970>1991; Corcel II 1977>1986; Del Rey 1981>1991; Pampa 1982>1997; | J12: TU - Leve | K12: FORD | L12: BE3M3M104A | M12: 87089990 | N12: 01.075.00 | O12: 1.62 | P12: 7898233430083 | Q12: 1
A13: AL-09 | B13: 127.16923 | C13: ='Lista de Preço 02_2022'!$B13*0.9*0.9*0.9*0.9*0.9*0.97 -> 72.839394 | D13: ='Lista de Preço 02_2022'!$C13*1.1712 -> 85.309498 | E13: 3.25 | F13: 0.18 | G13: Leve | H13: CUBO DE RODA | I13: FORD - Courier 16V 1997 >; Ecosport todos 2003 >; Ecosport Todos 2003>; Escort (menos 2.0i) 1993 > 1996; Escort 1.6 1992 >; Escort Hobby 1993 > 1996; Escort MK5 1993 >; Escort S.W 1.6 2000 >; Escort S.W 1.8i 16V 1996 >; Escort S.W Zetec 1996 >; Escort Zetec 1.6 2000 >; Escort Zetec 1.8 16V 1996 >; Fiesta 1.4 16V 1996 > 1996; Fiesta III - 1.1 / 1.4 03/1989>1995; Fiesta III 1.8 XR2i 16V 02/1992>1996; Fiesta IV 1.2i 08/1995>2002; Fiesta IV 1.4i 16V 04/1996>2002; Fiesta Sedan 2002>; Focus 1.6 8V 2000>2008; Focus 1.8 16V 2000>2008; Focus 2.0 2000>2008; KA todos 1997 >; Verona todos (menos 2.0i) 1993 > 1996; Verona Zetec 1996 >; VOLKSWAGEN - Logus todos s/ABS 1993 > 1997; Pointer CL/GL (menos GTI 2.0) 1994 > 1997; | J13: CR - Leve | K13: FORD | L13: 547407601 | M13: 87089990 | N13: 01.075.00 | O13: 1.61 | P13: 7898233430090 | Q13: 1
A14: AL-10 | B14: 189.94393 | C14: ='Lista de Preço 02_2022'!$B14*0.9*0.9*0.9*0.9*0.9*0.97 -> 108.79519 | D14: ='Lista de Preço 02_2022'!$C14*1.1712 -> 127.42093 | E14: 3.25 | F14: 0.18 | G14: Leve | H14: CUBO DE RODA | I14: FORD - Belina II 1975 > 1991; Corcel I/II 1975 > 1983; Del Rey todos 1981 > 1991; Pampa 4WD 1982 >; Pampa todos 1986 >; Scala L 1983 >; | J14: CR - Leve | K14: FORD | L14: 87EU1104AA | M14: 87089990 | N14: 01.075.00 | O14: 2.102 | P14: 7898233430106 | Q14: 1
A15: AL-100 | B15: 102.02972 | C15: ='Lista de Preço 02_2022'!$B15*0.9*0.9*0.9*0.9*0.9*0.97 -> 58.440103 | D15: ='Lista de Preço 02_2022'!$C15*1.1712 -> 68.445049 | E15: 3.25 | F15: 0.18 | G15: Leve | H15: PONTA DE EIXO | I15: CHEVROLET / GM - Kadett Todos 1989>; Monza Todos 1985>; | J15: PE - Leve | K15: CHEVROLET | L15: 94628790 | M15: 87089990 | N15: 01.075.00 | O15: 0.89 | P15: 7898233430557 | Q15: 1
A16: AL-1000 | B16: 200.31849 | C16: ='Lista de Preço 02_2022'!$B16*0.9*0.9*0.9*0.9*0.9*0.97 -> 114.73749 | D16: ='Lista de Preço 02_2022'!$C16*1.1712 -> 134.38054 | E16: 3.25 | F16: 0.18 | G16: Leve | H16: HOMOCINETICA | I16: VOLKSWAGEN - Kombi 1.6 02.1978/12.1997; Variant II 1978>1981; | J16: PH - Utilitario | K16: VOLKSWAGEN | L16: 153169/ 156169 | M16: 87089990 | N16: 01.075.00 | O16: 1.688 | P16: 7898233435088 | Q16: 1
A17: AL-1001 | B17: 204.20817 | C17: ='Lista de Preço 02_2022'!$B17*0.9*0.9*0.9*0.9*0.9*0.97 -> 116.9654 | D17: ='Lista de Preço 02_2022'!$C17*1.1712 -> 136.98987 | E17: 3.25 | F17: 0.18 | G17: Leve | H17: HOMOCINETICA | I17: VOLKSWAGEN - Kombi 1.4 Flex 2006 > 2013; Kombi 1.6 01/1998 > 2013; | J17: PH - Utilitario | K17: VOLKSWAGEN | L17: 546.759/ 546/749 | M17: 87089990 | N17: 01.075.00 | O17: 1.688 | P17: 7898233435071 | Q17: 1
A18: AL-1003 | B18: 175.10741 | C18: ='Lista de Preço 02_2022'!$B18*0.9*0.9*0.9*0.9*0.9*0.97 -> 100.2972 | D18: ='Lista de Preço 02_2022'!$C18*1.1712 -> 117.46808 | E18: 3.25 | F18: 0.18 | G18: Leve | H18: HOMOCINETICA | I18: FORD - Belina 1.8 08.1989/04.1991; Del Rey 1.6 08.1989/04.1991; Del Rey 1.8 08.1989/04.1991; Escort 1.6 12.1992/12.1996; Escort 1.8 05.1989/11.1992; Pampa 1.8 08.1989/12.1997; Royale 1.8 02.1991/11.1992; Royale 2.0 02.1991/11.1992; Scala 1.8 08.1989/04.1991; Versailles 1.8 01.1990/09.1993; Versailles 2.0 01.1991/11.1992; VOLKSWAGEN - Apollo 1.8 1990/1992; Carat 1.8 1987/1997; Carat 2.0 1987/1997; Gol 1.0 16V 1997>2001; Gol 1.0 8V 1992>1996; Gol 1.3 8V 1980>1986; Gol 1.6 1994/2006; Gol 1.6 8V 1986>1994; Gol 1.6 8V AE 1989>1994; Gol 1.6 8V Refr. Ar 1982>1986; Gol 1.8 8V 1982/1994; Gol 1.8 8V 1994/2006; Gol 2.0 8V 1988/1994; Logus 1.6 1993/1996; Parati 1.0 16V 1997>; Parati 1.6 8V 1982>1996; Parati 1.6 8V 1994/...; Parati 1.8 8V 1982/1995; Parati 2.0 8V 1988/1995; Passat 1.5 1975>1986; Passat 1.6 1975>1988; Passat 1.8 1987/1988; Quantum 1.8 1986/1992; Quantum 2.0 8V 1986/1992; Santana 1.8 1984/1992; Santana 2.0 1984/1992; Saveiro 1.3 / 1.6 1984>1986; Saveiro 1.6 1996/...; Saveiro 1.6 AE 1987>1995; Saveiro 1.8 (AP) 1989/1995; Saveiro 1.8 1996/...; Saveiro 2.0 (AP) 1989/1995; Voyage 1.5 1982>1989; Voyage 1.6 1987>1989; Voyage 1.8 8V 1986/1987; | J18: PH - Leve | K18: VOLKSWAGEN | L18: 146139 | M18: 87089990 | N18: 01.075.00 | O18: 1.432 | P18: 7898233435057 | Q18: 1
A19: AL-1004 | B19: 183.86278 | C19: ='Lista de Preço 02_2022'!$B19*0.9*0.9*0.9*0.9*0.9*0.97 -> 105.31206 | D19: ='Lista de Preço 02_2022'!$C19*1.1712 -> 123.34149 | E19: 3.25 | F19: 0.18 | G19: Leve | H19: HOMOCINETICA | I19: VOLKSWAGEN - Fox 1.0 8V 2009>; Gol 1.0 8V - G5 2009>; Voyage 1.0 8V 2009>; | J19: PH - Leve | K19: VOLKSWAGEN | L19: 5U0 498103 | M19: 87089990 | N19: 01.075.00 | O19: 1.434 | P19: 7899823502487 | Q19: 1
A20: AL-1008 | B20: 297.19776 | C20: ='Lista de Preço 02_2022'!$B20*0.9*0.9*0.9*0.9*0.9*0.97 -> 170.22754 | D20: ='Lista de Preço 02_2022'!$C20*1.1712 -> 199.37049 | E20: 3.25 | F20: 0.18 | G20: Leve | H20: HOMOCINETICA | I20: TOYOTA - Hilux SRV Turbo Diesel 2006>; Hilux SW 3.0 Turbo Diesel 2005>; Hilux SW4 2.5 - Turbo Diesel 2005>; | J20: PH - Utilitario | K20: TOYOTA | L20: HILUX-SW/SRV | M20: 87089990 | N20: 01.075.00 | O20: 3.954 | P20: 7899823502494 | Q20: 1
A21: AL-101 | B21: 94.471963 | C21: ='Lista de Preço 02_2022'!$B21*0.9*0.9*0.9*0.9*0.9*0.97 -> 54.111207 | D21: ='Lista de Preço 02_2022'!$C21*1.1712 -> 63.375046 | E21: 3.25 | F21: 0.18 | G21: Leve | H21: PONTA DE EIXO | I21: CHEVROLET / GM - Agile 2010>; Celta 2001>; Corsa Classic/ Pick Up/ HatcH/ Sedan/ Wagon ; Prisma 2007>; Tigra ; | J21: PE - Leve | K21: CHEVROLET | L21: 90129572 | M21: 87089990 | N21: 01.075.00 | O21: 0.896 | P21: 7898233430564 | Q21: 1
A22: AL-1010 | B22: 141.12726 | C22: ='Lista de Preço 02_2022'!$B22*0.9*0.9*0.9*0.9*0.9*0.97 -> 80.834207 | D22: ='Lista de Preço 02_2022'!$C22*1.1712 -> 94.673023 | E22: 3.25 | F22: 0.18 | G22: Leve | H22: HOMOCINETICA | I22: FORD - Royale 1.8 1984/1992; Royale 2.0 1984/1992; Versailles 1.8 s/ABS 1984/1992; Versailles 2.0 s/ABS 1984/1992; VOLKSWAGEN - Carat 1.8 1987/1997; Carat 2.0 1987/1997; Gol 1.0 Mi - 8V/ 16V 1997>2001; Gol 1.0 Plus 1997>; Gol 1.6 1986/1994; Gol 1.6/ 1.8 11/1999>; Gol 1.8 1986/1994; Gol 2.0 1988/1994; Parati 1.0 Mi 16V 1997>2001; Parati 1.6 1986/1996; Parati 1.6 8V 1994>; Parati 1.8 1986/1996; Parati 1.8 8V 1996>; Passat 1.6 1986/1988; Passat 1.8 1975/1988; Quantum 1.8 8V 1986/1992; Quantum 2.0 8V 1986/1992; Santana s/ ABS 1984/1992; Saveiro 1.6 (AE) 1987/1995; Saveiro 1.6 / 1.8 08/1996; Saveiro 1.8 (AP) 1989/1995; Saveiro 2.0 1989/1995; Voyage 1.6 1986/1996; Voyage 1.8 1986/1996; | J22: PH - Leve | K22: VOLKSWAGEN | L22: 325-129/A | M22: 87089990 | N22: 01.075.00 | O22: 1.734 | P22: 7898233435187 | Q22: 1
A23: AL-1011 | B23: 148.58782 | C23: ='Lista de Preço 02_2022'!$B23*0.9*0.9*0.9*0.9*0.9*0.97 -> 85.107433 | D23: ='Lista de Preço 02_2022'!$C23*1.1712 -> 99.677825 | E23: 3.25 | F23: 0.18 | G23: Leve | H23: HOMOCINETICA | I23: FIAT - 128 1984/1986; Brio 1984/1994; Duna 1984/1994; Elba 1.3 1987/1996; Elba 1.5 1987/1996; Elba 1.6 1987/1996; Fiorino 1.0 1995/2000; Fiorino 1.3 1980/2006; Fiorino 1.5 1980/2006; Fiorino 1.6 1980/2006; Premio 1.3 1985/1995; Premio 1.5 1985/1995; Premio 1.6 1985/1995; Uno 1.0 1991/1995; Uno 1.3 1984/1996; Uno 1.5 1984/1996; Uno 1.5R 1984/1996; Uno 1.6 1984/1996; Uno 1.6R 1984/1996; Uno 1050 - s/ ABS 1985/1991; | J23: PH - Leve | K23: FIAT | L23: 515-339 | M23: 87089990 | N23: 01.075.00 | O23: 1.81 | P23: 7898233435194 | Q23: 1
A24: AL-1013 | B24: 195.94766 | C24: ='Lista de Preço 02_2022'!$B24*0.9*0.9*0.9*0.9*0.9*0.97 -> 112.23398 | D24: ='Lista de Preço 02_2022'!$C24*1.1712 -> 131.44844 | E24: 3.25 | F24: 0.18 | G24: Leve | H24: HOMOCINETICA | I24: FORD - Belina 1.8 1989/1991; Del Rey 1.6 1989/1991; Del Rey 1.8 1989/1991; Pampa 1.8 - 4x2 09.1989/1997; Scala 1.8 1989/1997; | J24: PH - Leve | K24: FORD | L24: 1105-149 | M24: 87089990 | N24: 01.075.00 | O24: 2.034 | P24: 7898233435217 | Q24: 1
A25: AL-1014 | B25: 185.30146 | C25: ='Lista de Preço 02_2022'!$B25*0.9*0.9*0.9*0.9*0.9*0.97 -> 106.1361 | D25: ='Lista de Preço 02_2022'!$C25*1.1712 -> 124.3066 | E25: 3.25 | F25: 0.18 | G25: Leve | H25: HOMOCINETICA | I25: FORD - Belina 1971/1999; Corcel 1971/1999; Del Rey 1971/1999; Pampa 4x2 1971/1999; Pampa 4x4 1983/1997; Scala 1.6 1981/1989; | J25: PH - Leve | K25: FORD | L25: 295-149 | M25: 87089990 | N25: 01.075.00 | O25: 2.046 | P25: 7898233435224 | Q25: 1
A26: AL-1015 | B26: 170.17481 | C26: ='Lista de Preço 02_2022'!$B26*0.9*0.9*0.9*0.9*0.9*0.97 -> 97.471927 | D26: ='Lista de Preço 02_2022'!$C26*1.1712 -> 114.15912 | E26: 3.25 | F26: 0.18 | G26: Leve | H26: HOMOCINETICA | I26: VOLKSWAGEN - Gol 1975/1986; Parati 1975/1986; Passat 1975/1986; Saveiro 1975/1986; Voyage 1975/1986; | J26: PH - Leve | K26: VOLKSWAGEN | L26: 325-129 | M26: 87089990 | N26: 01.075.00 | O26: 1.712 | P26: 7898233435231 | Q26: 1
A27: AL-1016 | B27: 201.68866 | C27: ='Lista de Preço 02_2022'!$B27*0.9*0.9*0.9*0.9*0.9*0.97 -> 115.52228 | D27: ='Lista de Preço 02_2022'!$C27*1.1712 -> 135.2997 | E27: 3.25 | F27: 0.18 | G27: Leve | H27: HOMOCINETICA | I27: CHEVROLET / GM - Ipanema 09/1993>12/1997; Ipanema 1.8 1989/1993; Ipanema 2.0 1989/1997; Kadett 09/1993>12/1997; Kadett 1.8 1989/1993; Kadett 2.0 1989/1997; Monza 09/1993>12/1997; Monza 1.6 1982/1993; Monza 1.8 1982/1993; Monza 2.0 1985/1993; Vectra 1.8 / 2.0 - s/ABS 1993>1996; | J27: PH - Leve | K27: CHEVROLET | L27: 1291-419 | M27: 87089990 | N27: 01.075.00 | O27: 2.392 | P27: 7898233435248 | Q27: 1
A28: AL-1017 | B28: 151.26172 | C28: ='Lista de Preço 02_2022'!$B28*0.9*0.9*0.9*0.9*0.9*0.97 -> 86.638976 | D28: ='Lista de Preço 02_2022'!$C28*1.1712 -> 101.47157 | E28: 3.25 | F28: 0.18 | G28: Leve | H28: HOMOCINETICA | I28: CHEVROLET / GM - Celta 1.0 8V - s/ ABS 2000/...; Celta 1.4 8V - s/ ABS 2000/...; Corsa 1.0 - s/ ABS 1994/2003; Corsa 1.0 Classic - s/ ABS 2004/2007; Corsa 1.4 - s/ ABS 1994/2003; Corsa 1.6 - s/ ABS 1994/2003; Corsa 1.6 Classic - s/ ABS 2004/2007; Corsa Pick Up 1.6 8V - s/ ABS 1995/2003; Corsa Sedan 1.0 - s/ ABS 1994/2003; Corsa Sedan 1.6 - s/ ABS 1994/2003; Corsa Wagon 1.0 - s/ ABS 1994/2003; Corsa Wagon 1.6 - s/ ABS 1994/2003; Montana 1.4 8V - Eixo GKN - s/ ABS 2010/...; Novo Corsa 1.0 8V - s/ ABS 2002/...; Novo Corsa 1.4 8V - s/ ABS 2002/...; Prisma 1.0 8V Flex - s/ ABS 2007/...; Prisma 1.4 8V Flex - s/ ABS 2007/...; | J28: PH - Leve | K28: CHEVROLET | L28: 1355-499 | M28: 87089990 | N28: 01.075.00 | O28: 1.856 | P28: 7898233435255 | Q28: 1
A29: AL-1018 | B29: 203.71651 | C29: ='Lista de Preço 02_2022'!$B29*0.9*0.9*0.9*0.9*0.9*0.97 -> 116.68379 | D29: ='Lista de Preço 02_2022'!$C29*1.1712 -> 136.66005 | E29: 3.25 | F29: 0.18 | G29: Leve | H29: HOMOCINETICA | I29: FORD - Royale s/ ABS 11.1992/12.1995; Versailles s/ ABS 11.1992/12.1995; VOLKSWAGEN - Gol 2.0 8V - s/ ABS 10.1994/...; Gol 2.0 8V 1996/...; Parati 2.0 8V s/ABS 1996/...; Quantum 1.8 8V - s/ ABS 1992/2002; Quantum 2.0 8V - s/ ABS 1992/2002; Santana 1.8 - s/ ABS 1992/2007; Santana 2.0 - s/ ABS 1992/2007; Saveiro 2.0 1996/...; | J29: PH - Leve | K29: VOLKSWAGEN | L29: 1361-419 | M29: 87089990 | N29: 01.075.00 | O29: 2.154 | P29: 7898233435262 | Q29: 1
A30: AL-102 | B30: 232.07313 | C30: ='Lista de Preço 02_2022'!$B30*0.9*0.9*0.9*0.9*0.9*0.97 -> 132.92576 | D30: ='Lista de Preço 02_2022'!$C30*1.1712 -> 155.68264 | E30: 3.25 | F30: 0.18 | G30: Leve | H30: CUBO DE RODA | I30: CHEVROLET / GM - Astra 1.8 1994 > 1998; Astra 1.8 8V 1999 >; Astra 2.0 16V 1999 >; Astra 2.0 8V < 1996; Astra S.W < 1996; Chevy todos 1980 >; Corsa Pick up todos; Ipanema todos 1990 > 1998; Kadett todos 1989 > 1998; Marajó todos 1973 >; Monza todos 1982 > 1997; Tigra 1.4 / 1.6 1998 >; Tracker todos 2001 >; Vectra 2.0 16V 1994 > 1999; Vectra 2.0 1994 > 1996; Vectra 2.0 8V 1997 > 1999; Vectra 2.2 16V 1997 > 1999; Vectra 2.2 8V 1999 >; | J30: CR - Leve | K30: CHEVROLET | L30: 90157011 | M30: 87089990 | N30: 01.075.00 | O30: 2.178 | P30: 7898233430571 | Q30: 1
A31: AL-1020 | B31: 180.12222 | C31: ='Lista de Preço 02_2022'!$B31*0.9*0.9*0.9*0.9*0.9*0.97 -> 103.16956 | D31: ='Lista de Preço 02_2022'!$C31*1.1712 -> 120.83219 | E31: 3.25 | F31: 0.18 | G31: Leve | H31: HOMOCINETICA | I31: FORD - Courier 1.3 1997/1999; Fiesta Endura GII - 1.0 s/ ABS 1996/1999; Fiesta Endura GII - 1.3 s/ ABS 1996/1999; Ka Endura - 1.0 s/ ABS 1996/1999; Ka Endura - 1.3 s/ ABS 1996/1999; | J31: PH - Leve | K31: FORD | L31: 1481-609 | M31: 87089990 | N31: 01.075.00 | O31: 1.654 | P31: 7898233435286 | Q31: 1
A32: AL-1021 | B32: 179.4851 | C32: ='Lista de Preço 02_2022'!$B32*0.9*0.9*0.9*0.9*0.9*0.97 -> 102.80463 | D32: ='Lista de Preço 02_2022'!$C32*1.1712 -> 120.40478 | E32: 3.25 | F32: 0.18 | G32: Leve | H32: HOMOCINETICA | I32: FIAT - Fiorino 1.6 1996/2006; Palio 1.5 1996/2000; Palio 1.6 8V 1996/2000; Palio 1.7 Diesel 1996/2000; Palio Weekend 1.5 1997/2000; Palio Weekend 1.6 8V 1997/2000; Siena 1.5 1997/2000; Siena 1.6 16V 1997/2000; Siena 1.6 8V 1997/2000; Siena 1.7 - s/ ABS 1997 > 2000; | J32: PH - Leve | K32: FIAT | L32: 1501/669 | M32: 87089990 | N32: 01.075.00 | O32: 1.864 | P32: 7898233435293 | Q32: 1
A33: AL-1022 | B33: 213.19122 | C33: ='Lista de Preço 02_2022'!$B33*0.9*0.9*0.9*0.9*0.9*0.97 -> 122.11066 | D33: ='Lista de Preço 02_2022'!$C33*1.1712 -> 143.01601 | E33: 3.25 | F33: 0.18 | G33: Leve | H33: HOMOCINETICA | I33: FORD - Escort 1.8 1993/1996; Escort 2.0 1993/1996; Verona 1.8 1993/1996; Verona 2.0 1993/1996; VOLKSWAGEN - Logus 1.8 1992/1996; Logus 2.0 1992/1996; Pointer 1.8 1993/1996; Pointer 2.0 1993/1996; | J33: PH - Leve | K33: FORD | L33: 1171-419 | M33: 87089990 | N33: 01.075.00 | O33: 2.278 | P33: 7898233435309 | Q33: 1
A34: AL-1023 | B34: 170.4968 | C34: ='Lista de Preço 02_2022'!$B34*0.9*0.9*0.9*0.9*0.9*0.97 -> 97.656355 | D34: ='Lista de Preço 02_2022'!$C34*1.1712 -> 114.37512 | E34: 3.25 | F34: 0.18 | G34: Leve | H34: HOMOCINETICA | I34: FIAT - Fiorino 1.3 8V / 1.3 16V - Fire - s/ ABS 2000>2009; Fiorino 1.6 8V - S/ ABS 1994>1995; Palio 1.0 8V - s/ ABS 1996>2000; Palio 1.3 s/ ABS 1996>2008; Palio Weekend - 1.0 8V - s/ ABS 1998>2008; Siena 1.0 8V - s/ ABS 1998>2088; Uno Mile 1.0 8V - S/ABS 1991>2012; | J34: PH - Leve | K34: FIAT | L34: 1491-599 | M34: 87089990 | N34: 01.075.00 | O34: 1.866 | P34: 7898233435316 | Q34: 1
A35: AL-1024 | B35: 219.65156 | C35: ='Lista de Preço 02_2022'!$B35*0.9*0.9*0.9*0.9*0.9*0.97 -> 125.81099 | D35: ='Lista de Preço 02_2022'!$C35*1.1712 -> 147.34983 | E35: 3.25 | F35: 0.18 | G35: Leve | H35: HOMOCINETICA | I35: FIAT - Tempra 2.0 s/ ABS 1992/1999; Tipo 2.0 s/ ABS 1992/1999; | J35: PH - Leve | K35: FIAT | L35: 1111-539 | M35: 87089990 | N35: 01.075.00 | O35: 2.28 | P35: 7898233435323 | Q35: 1
A36: AL-1025 | B36: 195.38589 | C36: ='Lista de Preço 02_2022'!$B36*0.9*0.9*0.9*0.9*0.9*0.97 -> 111.91221 | D36: ='Lista de Preço 02_2022'!$C36*1.1712 -> 131.07158 | E36: 3.25 | F36: 0.18 | G36: Leve | H36: HOMOCINETICA | I36: FORD - Escort 1.0 Hobby (AE) 1993/...; Escort 1.6 Hobby 1993/...; Escort 1.8 1989/1992; Verona 1.8 1990/1993; VOLKSWAGEN - Apollo 1.8 1990/1992; | J36: PH - Leve | K36: FORD | L36: 531-279/A | M36: 87089990 | N36: 01.075.00 | O36: 1.754 | P36: 7898233435330 | Q36: 1
A37: AL-1027 | B37: 200.27054 | C37: ='Lista de Preço 02_2022'!$B37*0.9*0.9*0.9*0.9*0.9*0.97 -> 114.71002 | D37: ='Lista de Preço 02_2022'!$C37*1.1712 -> 134.34837 | E37: 3.25 | F37: 0.18 | G37: Leve | H37: HOMOCINETICA | I37: FORD - Courier 1.4 s/ ABS 1997/2006; Escort 1.6 Zetec Rocam - s/ ABS 1997/2003; Escort 1.8 16V - Zetec Rocam - s/ ABS 1997/2003; Fiesta 1.4 16V Zetec - s/ ABS 1996/2006; Fiesta 1.8 (Argentino) - s/ ABS 1996/2006; | J37: PH - Leve | K37: FORD | L37: 1525-279 | M37: 87089990 | N37: 01.075.00 | O37: 1.848 | P37: 7898233435354 | Q37: 1
A38: AL-1028 | B38: 194.43742 | C38: ='Lista de Preço 02_2022'!$B38*0.9*0.9*0.9*0.9*0.9*0.97 -> 111.36895 | D38: ='Lista de Preço 02_2022'!$C38*1.1712 -> 130.43531 | E38: 3.25 | F38: 0.18 | G38: Leve | H38: HOMOCINETICA | I38: FORD - Escort 1.3 1983/1992; Verona 1.6 motor CHT 1983/1992; | J38: PH - Leve | K38: FORD | L38: 531-279 | M38: 87089990 | N38: 01.075.00 | O38: 1.74 | P38: 7898233435361 | Q38: 1
A39: AL-1029 | B39: 212.06675 | C39: ='Lista de Preço 02_2022'!$B39*0.9*0.9*0.9*0.9*0.9*0.97 -> 121.4666 | D39: ='Lista de Preço 02_2022'!$C39*1.1712 -> 142.26168 | E39: 3.25 | F39: 0.18 | G39: Leve | H39: HOMOCINETICA | I39: FORD - Courier 1.6 Zetec Rocam - s/ ABS 1999>2013; Ecosport 1.0 - 4x2 - Zetec Rocam - Supercharger s/ ABS 2002>2007; Ecosport 1.6 Zetec Rocam - s/ ABS 2003>2012; Fiesta 1.0 8V Zetec Rocam Supercharger - s/ ABS 2002>2014; Fiesta 1.6 8V Zetec Rocam - s/ ABS 2002>2012; Fiesta GII - 1.6 Zetec Rocam - s/ ABS 1999>2006; Focus 1.6 - Zetec Rocam 2003>10/2009; Focus 1.6 - Zetec Rocam 2006>2010; Ka 1.6 Zetec Rocam - s/ ABS 2000>2012; | J39: PH - Leve | K39: FORD | L39: 1735909 | M39: 87089990 | N39: 01.075.00 | O39: 1.678 | P39: 7898233435378 | Q39: 1
A40: AL-103 | B40: 106.3061 | C40: ='Lista de Preço 02_2022'!$B40*0.9*0.9*0.9*0.9*0.9*0.97 -> 60.889511 | D40: ='Lista de Preço 02_2022'!$C40*1.1712 -> 71.313795 | E40: 3.25 | F40: 0.18 | G40: Leve | H40: CUBO DE RODA | I40: CHEVROLET / GM - Calibra 2.0 16V 4x4 06/1990 > 02/1994; Vectra 2.0 8V 1997 > 2005; Vectra 2.2 8V 1997 > 2005; | J40: CR - Leve | K40: FORD | L40: 93271760 | M40: 87089990 | N40: 01.075.00 | O40: 1.478 | P40: 7898233430588 | Q40: 1
...
